<?xml version="1.0" ?>
<robot name="jian_robot" xmlns:xacro="http://www.ros.org/wiki/xacro">

    <!-- Defining the colors used in this robot -->
    <material name="Black">
        <color rgba="0 0 0 1"/>
    </material>

    <material name="White">
        <color rgba="1 1 1 1"/>
    </material>

    <material name="Blue">
        <color rgba="0 0 1 1"/>
    </material>

    <material name="Red">
        <color rgba="1 0 0 1"/>
    </material>



    <xacro:macro name="jian_robot_body">
    <link name="base_link">
        <inertial>
                <origin xyz="0 0 0"/>
                <mass value="10" />
                <inertia ixx="1" ixy="0.0" ixz="0.0"
                         iyy="1" iyz="0.0" izz="1" />
        </inertial>
        <visual>
            <origin xyz=" 0 0 0.35" rpy="0 0 0" />
            <geometry>
                <box size="1.2 0.8 0.5" />
            </geometry>
            <material name="yellow">
                <color rgba="1 0.4 0 1"/>
            </material>
        </visual>

       <collision>
	    <origin xyz=" 0 0 0.35" rpy="0 0 0" />
            <geometry>
                <box size="1.2 0.8 0.5" />
            </geometry>
       </collision>
    </link>
    <gazebo reference="base_link">
            <material>Gazebo/Blue</material>
    </gazebo>
    <joint name="base_left_motor_joint" type="fixed">
        <origin xyz="-0 0.4 0.1" rpy="0 0 0" />        
        <parent link="base_link"/>
        <child link="left_motor" />
    </joint>

    <link name="left_motor">
        <inertial>
                <origin xyz="0 0 0"/>
                <mass value="1" />
                <inertia ixx="0.1" ixy="0.0" ixz="0.0"
                         iyy="0.1" iyz="0.0" izz="0.1" />
        </inertial>
        <visual>
            <origin xyz="0 0 0" rpy="1.5707 0 0" />
            <geometry>
                <cylinder radius="0.02" length = "0.08"/>
            </geometry>
            <material name="gray">
                <color rgba="0.75 0.75 0.75 1"/>
            </material>
        </visual>
       <collision>
	    <origin xyz="0 0 0" rpy="1.5707 0 0" />
            <geometry>
                <cylinder radius="0.02" length = "0.08"/>
            </geometry>
       </collision>
    </link>

    <joint name="left_wheel_joint" type="continuous">
        <origin xyz="0 -0.4485 0.1" rpy="0 0 0"/>
        <parent link="base_link"/>
        <child link="left_wheel_link"/>
        <axis xyz="0 1 0"/>
    </joint>
   <link name="left_wheel_link">
        <inertial>
                <origin xyz="0 0 0"/>
                <mass value="1" />
                <inertia ixx="0.1" ixy="0.0" ixz="0.0"
                         iyy="0.1" iyz="0.0" izz="0.1" />
        </inertial>
        <visual>
            <origin xyz="0 0 0" rpy="1.5707 0 0" />
            <geometry>
                <cylinder radius="0.1" length = "0.067"/>
            </geometry>
            <material name="white">
                <color rgba="1 1 1 0.9"/>
            </material>
        </visual>
        <collision>
	    <origin xyz="0 0 0" rpy="1.5707 0 0" />
            <geometry>
                <cylinder radius="0.1" length = "0.067"/>
            </geometry>
       </collision>
    </link>
    <gazebo reference="left_wheel_link">
            <material>Gazebo/Black</material>
    </gazebo>

    <!-- Transmission is important to link the joints and the controller -->
    <transmission name="left_wheel_joint_trans">
	<type>transmission_interface/SimpleTransmission</type>
	<joint name="left_wheel_joint" />
	<actuator name="left_motor">
	<hardwareInterface>VelocityJointInterface</hardwareInterface>
	<mechanicalReduction>1</mechanicalReduction>
	</actuator>
    </transmission>

    
    <joint name="base_right_motor_joint" type="fixed">
        <origin xyz="-0 -0.4 0.1" rpy="0 0 0" />        
        <parent link="base_link"/>
        <child link="right_motor" />
    </joint>
    <link name="right_motor">
        <inertial>
                <origin xyz="0 0 0"/>
                <mass value="1" />
                <inertia ixx="0.1" ixy="0.0" ixz="0.0"
                         iyy="0.1" iyz="0.0" izz="0.1" />
        </inertial>
        <visual>
            <origin xyz="0 0 0" rpy="1.5707 0 0" />
            <geometry>
                <cylinder radius="0.02" length = "0.08" />
            </geometry>
            <material name="gray">
                <color rgba="0.75 0.75 0.75 1"/>
            </material>
        </visual>
        <collision>
	    <origin xyz="0 0 0" rpy="1.5707 0 0" />
            <geometry>
                <cylinder radius="0.02" length = "0.08" />
            </geometry>
       </collision>
    </link>

    <joint name="right_wheel_joint" type="continuous">
        <origin xyz="-0 0.4485 0.1" rpy="0 0 0"/>
        <parent link="base_link"/>
        <child link="right_wheel_link"/>
        <axis xyz="0 1 0"/>
    </joint>

    <link name="right_wheel_link">
        <inertial>
                <origin xyz="0 0 0"/>
                <mass value="1" />
                <inertia ixx="0.1" ixy="0.0" ixz="0.0"
                         iyy="0.1" iyz="0.0" izz="0.1" />
        </inertial>
        <visual>
            <origin xyz="0 0 0" rpy="1.5707 0 0" />
            <geometry>
                <cylinder radius="0.1" length = "0.067"/>
            </geometry>
            <material name="white">
                <color rgba="1 1 1 0.9"/>
            </material>
        </visual>
        <collision>
	    <origin xyz="0 0 0" rpy="1.5707 0 0" />
            <geometry>
                <cylinder radius="0.1" length = "0.067"/>
            </geometry>
       </collision>
    </link>
    <gazebo reference="right_wheel_link">
            <material>Gazebo/Black</material>
    </gazebo>
    <!-- Transmission is important to link the joints and the controller -->
    <transmission name="right_wheel_joint_trans">
	<type>transmission_interface/SimpleTransmission</type>
	<joint name="right_wheel_joint" />
	<actuator name="right_motor">
	<hardwareInterface>VelocityJointInterface</hardwareInterface>
	<mechanicalReduction>1</mechanicalReduction>
	</actuator>
    </transmission>

    <joint name="front_caster_joint" type="fixed">
        <origin xyz="0.6 0 0.1" rpy="0 0 0"/>
        <parent link="base_link"/>
        <child link="front_caster_link"/>
    </joint>

    <link name="front_caster_link">
        <inertial>
                <origin xyz="0 0 0"/>
                <mass value="1" />
                <inertia ixx="0.1" ixy="0.0" ixz="0.0"
                         iyy="0.1" iyz="0.0" izz="0.1" />
        </inertial>
        <visual>
            <origin xyz="0 0 0" rpy="1.5707 0 0"/>
            <geometry>
                <sphere radius="0.1" />
            </geometry>
            <material name="black">
                <color rgba="0 0 0 0.95"/>
            </material>
        </visual>
        <collision>
	    <origin xyz="0 0 0" rpy="1.5707 0 0"/>
            <geometry>
                <sphere radius="0.1" />
            </geometry>
       </collision>
    </link>
    <link name="imu_link">
        <inertial>
                <origin xyz="0 0 0"/>
                <mass value="1" />
                <inertia ixx="0.1" ixy="0.0" ixz="0.0"
                         iyy="0.1" iyz="0.0" izz="0.1" />
        </inertial>
        <visual>
            <origin xyz="0 0 0" rpy="1.5707 0 0"/>
            <geometry>
                <sphere radius="0.05" />
            </geometry>
            <material name="red">
                <color rgba="1 0 0 0.95"/>
            </material>
        </visual>
        <collision>
	    <origin xyz="0 0 0" rpy="1.5707 0 0"/>
            <geometry>
                <sphere radius="0.05" />
            </geometry>
       </collision>

    </link>
    <gazebo reference="imu_link">
            <material>Gazebo/White</material>
    </gazebo>
    <joint name="imu_joint" type="fixed">
        <origin xyz="0.4 0 0.63" rpy="0 0 0"/>
        <parent link="base_link"/>
        <child link="imu_link"/>
    </joint>
    
        <gazebo reference="front_caster_link">
            <material>Gazebo/Black</material>
        </gazebo>
        <!-- plate Definitions -->
        <plate num="1"  parent="base_link" />

        <!-- controller -->
        <gazebo>
            <plugin name="differential_drive_controller" filename="libgazebo_ros_diff_drive.so">
                <rosDebugLevel>Debug</rosDebugLevel>
                <publishWheelTF>true</publishWheelTF>
                <robotNamespace>/</robotNamespace>
                <publishTf>1</publishTf>
                <publishWheelJointState>true</publishWheelJointState>
                <alwaysOn>true</alwaysOn>
                <updateRate>100.0</updateRate>
                <legacyMode>true</legacyMode>
                <leftJoint>left_wheel_joint</leftJoint>
                <rightJoint>right_wheel_joint</rightJoint>
                <wheelSeparation>0.897</wheelSeparation>
                <wheelDiameter>0.2</wheelDiameter>
                <broadcastTF>1</broadcastTF>
                <wheelTorque>30</wheelTorque>
                <wheelAcceleration>1.8</wheelAcceleration>
                <commandTopic>cmd_vel</commandTopic>
                <odometryFrame>odom</odometryFrame> 
                <odometryTopic>odom</odometryTopic> 
                <robotBaseFrame>base_footprint</robotBaseFrame>
            </plugin>
        </gazebo> 
</xacro:macro>
</robot>


















